<!DOCTYPE html>
<html lang="en">

<head>
  <title>Custom Promises</title>
</head>

<body>
  <script>
    function breathe(amount) {
      return new Promise((resolve, reject) => {
        if (amount < 500) {
          reject('That is too small of a value');
        }
        setTimeout(() => {
          resolve(`Done for ${amount} ms`)
        }, amount);
      });
    }

    // Higher order function are used for error handling

    function catchErrors(fn) {
      return function(...args) {
        return fn(...args).catch((err) => {
          console.error('Ohhh nooo!!!!');
          console.error(err);
        });
      }
    }

    async function go(name, last) {
        console.log(`Starting for ${name} ${last}`);
        const res = await breathe(1000);
        console.log(res);
        const res2 = await breathe(300);
        console.log(res2);
        const res3 = await breathe(900);
        console.log(res3);
        const res4 = await breathe(800);
        console.log(res4);
        console.log('end');
    }

    // In order to use await inside, you have to put an async in front of the function

    const wrappedFunction = catchErrors(go);

    wrappedFunction('Freddy', 'Al');
  </script>
</body>

</html>